Workbook

Sheet Instructions
B2: Australian Skills Guarantee
B3: Reporting Worksheet Instructions
B6: The Skills Guarantee Reporting Worksheet is provided to enable suppliers and relevant entities of projects subject to the Australian Skills Guarantee to fulfil their reporting obligations. This template provides an interim solution until the department's online reporting tool is available.
B7: DEWR collates all reporting information across all relevant entities and eligible projects to determine overall program performance.
B8: This template is to be used for all major ICT, major construction and flagship construction projects under the Australian Skills Guarantee.
B9: For more information on the Australian Skills Guarantee or the reporting obligations, visit:
B10: https://www.dewr.gov.au/australian-skills-guarantee
B12: Privacy and collection of personal information
B13: Before reporting any personal information, please confirm that the individual has read, understood and agreed to the collection, use and disclosure of their personal information as set out in the privacy notice for the Australian Skills Guarantee available here:
B14: https://www.dewr.gov.au/australian-skills-guarantee/resources/australian-skills-guarantee-privacy-notice
B15: The Department of Employment and Workplace Relations, and the relevant contracting Commonwealth department or agency, also collects personal information about the personnel who submit the Reporting Worksheet. This information will be used to administer the Australian Skills Guarantee, including to contact personnel if further information is required.
B16: Your personal information is protected by law, including the Privacy Act 1988 and will not be disclosed to any third parties, including overseas recipients, unless you consent or it is required or authorised by law.
... B26: Field types
C28: These fields are to capture inputs from suppliers and relevant entities.
C29: These are calculation fields presenting a value based on your inputs into the worksheet.
C30: These are reference fields, displaying information for ease of use that has been provided elsewhere in the worksheet.
B32: Project details
B33: This page is to be completed by the relevant entity to set up the project details.
B34: Information recorded should be entered exactly as per your contract with the supplier, and as per the details provided to AusTender.
B35: This page captures summary information describing the project, as well as the agreed Skills Guarantee targets and estimated total hours.
B36: If there is one or more variations to your contract while using this worksheet, please update the project details page to show the latest information for the value, timeline and estimated total hours.
B38: Gender Equality Action Plan
B39: Note: Flagship construction projects are required to propose higher targets for women and have a Gender Equality Action Plan (GEAP), which should be provided as an attachment when submitting this worksheet to the department.
B40: Potential suppliers for major construction and major ICT projects are also encouraged to submit a GEAP as part of their tender submission.
B41: Upon execution of the work order or contract, the GEAP (as submitted in the response to the approach to market) is considered to be approved by the relevant entity.
B43: Participant reporting
B44: This page is to be completed by the supplier.
B45: Suppliers should record the details of all apprentices and ICT cadets working on their project, and the hours worked to enable accurate reporting on Skills Guarantee targets. Suppliers must also record, track, and report this information on behalf of their sub-contractors.
... B66: Instructions: - Project scope clarified - Updated Privacy and collection of personal information section - Added note about consent under Participant reporting section - Updated Quarterly reports section to include a supplier declaration - Version history section added Project details: - Formatting of Agency contact details – Contact Phone number field - Formatting of Supplier contact details - Contact Phone number field - Amending ASG Requirements – Rationale drop down reason Participant reporting: - Note on privacy consent included - Updated Column title ‘Has USI?’ Quarter 1/2/3/4 reports: - Declaration inserted for suppliers to complete End of project report: - Contracting Agency Assessment – a new outcome has been added under the ‘Overall assessment outcome’ and with associated drop downs.

Sheet Project details
B2: Australian Skills Guarantee
B3: Project Summary details
B4: Use this sheet to report the summary and contact details of your project.
B6: Project overview
B7: Project name
B8: Eligible project type
B9: UNSPSC Category
B10: Primary project location
B11: Total estimated labour hours
B13: Contract details | E13: Workforce Targets
B14: Please enter details exactly as in the Contract Notice published on AusTender. | E14: Enter the estimated labour hours and, if required, update the default workforce targets as per the executed contract.
B15: Contract Number (CN ID) | E15: Financial Year | F15: Estimated labour hours | H15: Overall Apprentices / Cadets | I15: Women Apprentices / Cadets | J15: Women in Trades
B16: Agency | E16: 2025 | H16: 0.1 | I16: 0.06 | J16: 0.04
B17: Contract period start date | E17: 2026 | H17: 0.1 | I17: 0.07 | J17: 0.05
B18: Contract period end date | E18: 2027 | H18: 0.1 | I18: 0.08 | J18: 0.06
B19: Contract value (AUD) (inc. GST) | E19: 2028 | H19: 0.1 | I19: 0.09 | J19: 0.07
B20: Procurement method | E20: 2029 | H20: 0.1 | I20: 0.1 | J20: 0.08
B21: Supplier name | E21: 2030 | H21: 0.1 | I21: 0.11 | J21: 0.09
B22: Supplier ABN | E22: 2031 | H22: 0.1 | I22: 0.12 | J22: 0.1
B23: Latest variation number (CN ID) | E23: 2032 | H23: 0.1 | I23: 0.12 | J23: 0.1
B24: Latest variation type | E24: 2033 | H24: 0.1 | I24: 0.12 | J24: 0.1
E25: 2034 | H25: 0.1 | I25: 0.12 | J25: 0.1
B26: Agency contact details
B27: Contract Manager Name | E27: Total / Average | F27: =SUM(F16:F25) -> 0 | H27: =IFERROR(SUMPRODUCT(F16:F25,H16:H25)/F27,"INPUT DATA") -> INPUT DATA | I27: =IFERROR(SUMPRODUCT(F16:F25,I16:I25)/F27,"INPUT DATA") -> INPUT DATA | J27: =IFERROR(SUMPRODUCT(F16:F25,J16:J25)/F27,"INPUT DATA") -> INPUT DATA
B28: Contact email | E28: Remaining to allocate | F28: =C11-SUM(F16:F25) -> 0
B29: Contact phone number | F29: =IF(F28>0,"More to allocate",IF(F28<0,"Overestimated","Complete")) -> Complete
B30: Delegate name (if different)
B32: Supplier contact details
B33: Name
B34: Position
B35: Contact email
B36: Contact phone number
B37: Registered business address
B39: ASG Requirements
B40: Custom Skilled Workforce Targets | E40: =IF(C40="Yes","Update the default values above per financial year with the agreed targets in the executed Supplier contract.","")
B41: Is there a Gender Equality Action Plan? | E41: =IF(C41="Yes","Submit a copy of the Gender Equality Action Plan to the department when submitting this report.",IF(AND(C8='List values'!B5,'Project details'!C41="No"),"A GEAP is required for all Flagship projects.",""))
B43: In-scope for ASG | E43: =IF(C43="No","Provide the rationale below for ASG not being applicable before submitting to DEWR for confirmation.","")
B44: Rationale | E44: Other
B45: Comments

Sheet Project data
A1: Project name | B1: Eligible project type | C1: UNSPSC Category | D1: Primary project location | E1: Total estimated labour hours | F1: Contract Number (CN ID) | G1: Agency | H1: Contract period start date | I1: Contract period end date | J1: Contract value (AUD) (inc. GST) | K1: Procurement method | L1: Supplier name | M1: Supplier ABN | N1: Latest variation number (CN ID) | O1: Latest variation type | P1: Contract Manager Name | Q1: Contact Email | R1: Contact Phone number | S1: Delegate name (if different) | T1: Name | U1: Position | V1: Contact email | W1: Contact phone number | X1: Registered business address | Y1: Custom Skilled Workforce Targets | Z1: Is there a Gender Equality Action Plan | AA1: In-scope for ASG | AB1: Rationale | AC1: Other | AD1: Comments | AE1: 2025 Hours | AF1: 2025 Overall target | AG1: 2025 Women target | AH1: 2025 Women in trades target | AI1: 2026 Hours | AJ1: 2026 Overall target | AK1: 2026 Women target | AL1: 2026 Women in trades target | AM1: 2027 Hours | AN1: 2027 Overall target | AO1: 2027 Women target | AP1: 2027 Women in trades target | AQ1: 2028 Hours | AR1: 2028 Overall target | AS1: 2028 Women target | AT1: 2028 Women in trades target | AU1: 2029 Hours | AV1: 2029 Overall target | AW1: 2029 Women target | AX1: 2029 Women in trades target | AY1: 2030 Hours | AZ1: 2030 Overall target | BA1: 2030 Women target | BB1: 2030 Women in trades target | BC1: 2031 Hours | BD1: 2031 Overall target | BE1: 2031 Women target | BF1: 2031 Women in trades target | BG1: 2032 Hours | BH1: 2032 Overall target | BI1: 2032 Women target | BJ1: 2032 Women in trades target | BK1: 2033 Hours | BL1: 2033 Overall target | BM1: 2033 Women target | BN1: 2033 Women in trades target | BO1: 2034 Hours | BP1: 2034 Overall target | BQ1: 2034 Women target | BR1: 2034 Women in trades target
A2: ='Project details'!C7 -> 0 | B2: ='Project details'!C8 -> 0 | C2: ='Project details'!C9 -> 0 | D2: ='Project details'!C10 -> 0 | E2: ='Project details'!C11 -> 0 | F2: ='Project details'!C15 -> 0 | G2: ='Project details'!C16 -> 0 | H2: ='Project details'!C17 -> 0 | I2: ='Project details'!C18 -> 0 | J2: ='Project details'!C19 -> 0 | K2: ='Project details'!C20 -> 0 | L2: ='Project details'!C21 -> 0 | M2: ='Project details'!C22 -> 0 | N2: ='Project details'!C23 -> 0 | O2: ='Project details'!C24 -> 0 | P2: ='Project details'!C27 -> 0 | Q2: ='Project details'!C28 -> 0 | R2: ='Project details'!C29 -> 0 | S2: ='Project details'!C30 -> 0 | T2: ='Project details'!C33 -> 0 | U2: ='Project details'!C34 -> 0 | V2: ='Project details'!C35 -> 0 | W2: ='Project details'!C36 -> 0 | X2: ='Project details'!C37 -> 0 | Y2: ='Project details'!C40 -> 0 | Z2: ='Project details'!C41 -> 0 | AA2: ='Project details'!C43 -> 0 | AB2: ='Project details'!C44 -> 0 | AC2: ='Project details'!F44 -> 0 | AD2: ='Project details'!C45 -> 0 | AE2: ='Project details'!F16 -> 0 | AF2: ='Project details'!H16 -> 0.1 | AG2: ='Project details'!I16 -> 0.06 | AH2: ='Project details'!J16 -> 0.04 | AI2: ='Project details'!F17 -> 0 | AJ2: ='Project details'!H17 -> 0.1 | AK2: ='Project details'!I17 -> 0.07 | AL2: ='Project details'!J17 -> 0.05 | AM2: ='Project details'!F18 -> 0 | AN2: ='Project details'!H18 -> 0.1 | AO2: ='Project details'!I18 -> 0.08 | AP2: ='Project details'!J18 -> 0.06 | AQ2: ='Project details'!F19 -> 0 | AR2: ='Project details'!H19 -> 0.1 | AS2: ='Project details'!I19 -> 0.09 | AT2: ='Project details'!J19 -> 0.07 | AU2: ='Project details'!F20 -> 0 | AV2: ='Project details'!H20 -> 0.1 | AW2: ='Project details'!I20 -> 0.1 | AX2: ='Project details'!J20 -> 0.08 | AY2: ='Project details'!F21 -> 0 | AZ2: ='Project details'!H21 -> 0.1 | BA2: ='Project details'!I21 -> 0.11 | BB2: ='Project details'!J21 -> 0.09 | BC2: ='Project details'!F22 -> 0 | BD2: ='Project details'!H22 -> 0.1 | BE2: ='Project details'!I22 -> 0.12 | BF2: ='Project details'!J22 -> 0.1 | BG2: ='Project details'!F23 -> 0 | BH2: ='Project details'!H23 -> 0.1 | BI2: ='Project details'!I23 -> 0.12 | BJ2: ='Project details'!J23 -> 0.1 | BK2: ='Project details'!F24 -> 0 | BL2: ='Project details'!H24 -> 0.1 | BM2: ='Project details'!I24 -> 0.12 | BN2: ='Project details'!J24 -> 0.1 | BO2: ='Project details'!F25 -> 0 | BP2: ='Project details'!H25 -> 0.1 | BQ2: ='Project details'!I25 -> 0.12 | BR2: ='Project details'!J25 -> 0.1

Sheet Participant reporting
A1: Australian Skills Guarantee
A2: Participant details
A3: Use this sheet to report the details and hours of apprentices and ICT cadets working on your project for each reporting period.
A4: By submitting participant details, the supplier declares that all necessary consents have been obtained for collection, use and disclosure of the participants’ personal information, including to allow DEWR to verify it against other information held in Australian Apprenticeships records or the USI registry.
A5: Financial Year | B5: Quarter | C5: Surname | D5: First Name | E5: Date of Birth | F5: Apprentice ID | G5: ICT Cadet | H5: Has USI and consents to its use? | I5: Gender | J5: Trade | K5: Hours (on-site) | L5: Hours (off-site) | M5: Residential Post Code | N5: Participant Contact Number | O5: Participant Email

Sheet Participant data
A1: Finanicial Year | B1: Quarter | C1: Surname | D1: First Name | E1: Date of Birth | F1: Apprentice ID | G1: ICT Cadet | H1: Has USI? | I1: Gender | J1: Trade | K1: Hours (on-site) | L1: Hours (off-site) | M1: Residential Post Code | N1: Participant Contact Number | O1: Participant Email
A2: ='Participant reporting'!A6 -> 0 | B2: ='Participant reporting'!B6 -> 0 | C2: ='Participant reporting'!C6 -> 0 | D2: ='Participant reporting'!D6 -> 0 | E2: ='Participant reporting'!E6 -> 0 | F2: ='Participant reporting'!F6 -> 0 | G2: ='Participant reporting'!G6 -> 0 | H2: ='Participant reporting'!H6 -> 0 | ... O2: ='Participant reporting'!O6 -> 0
A3: ='Participant reporting'!A7 -> 0 | B3: ='Participant reporting'!B7 -> 0 | C3: ='Participant reporting'!C7 -> 0 | D3: ='Participant reporting'!D7 -> 0 | E3: ='Participant reporting'!E7 -> 0 | F3: ='Participant reporting'!F7 -> 0 | G3: ='Participant reporting'!G7 -> 0 | H3: ='Participant reporting'!H7 -> 0 | ... O3: ='Participant reporting'!O7 -> 0
A4: ='Participant reporting'!A8 -> 0 | B4: ='Participant reporting'!B8 -> 0 | C4: ='Participant reporting'!C8 -> 0 | D4: ='Participant reporting'!D8 -> 0 | E4: ='Participant reporting'!E8 -> 0 | F4: ='Participant reporting'!F8 -> 0 | G4: ='Participant reporting'!G8 -> 0 | H4: ='Participant reporting'!H8 -> 0 | ... O4: ='Participant reporting'!O8 -> 0
A5: ='Participant reporting'!A9 -> 0 | B5: ='Participant reporting'!B9 -> 0 | C5: ='Participant reporting'!C9 -> 0 | D5: ='Participant reporting'!D9 -> 0 | E5: ='Participant reporting'!E9 -> 0 | F5: ='Participant reporting'!F9 -> 0 | G5: ='Participant reporting'!G9 -> 0 | H5: ='Participant reporting'!H9 -> 0 | ... O5: ='Participant reporting'!O9 -> 0
A6: ='Participant reporting'!A10 -> 0 | B6: ='Participant reporting'!B10 -> 0 | C6: ='Participant reporting'!C10 -> 0 | D6: ='Participant reporting'!D10 -> 0 | E6: ='Participant reporting'!E10 -> 0 | F6: ='Participant reporting'!F10 -> 0 | G6: ='Participant reporting'!G10 -> 0 | H6: ='Participant reporting'!H10 -> 0 | ... O6: ='Participant reporting'!O10 -> 0
A7: ='Participant reporting'!A11 -> 0 | B7: ='Participant reporting'!B11 -> 0 | C7: ='Participant reporting'!C11 -> 0 | D7: ='Participant reporting'!D11 -> 0 | E7: ='Participant reporting'!E11 -> 0 | F7: ='Participant reporting'!F11 -> 0 | G7: ='Participant reporting'!G11 -> 0 | H7: ='Participant reporting'!H11 -> 0 | ... O7: ='Participant reporting'!O11 -> 0
A8: ='Participant reporting'!A12 -> 0 | B8: ='Participant reporting'!B12 -> 0 | C8: ='Participant reporting'!C12 -> 0 | D8: ='Participant reporting'!D12 -> 0 | E8: ='Participant reporting'!E12 -> 0 | F8: ='Participant reporting'!F12 -> 0 | G8: ='Participant reporting'!G12 -> 0 | H8: ='Participant reporting'!H12 -> 0 | ... O8: ='Participant reporting'!O12 -> 0
A9: ='Participant reporting'!A13 -> 0 | B9: ='Participant reporting'!B13 -> 0 | C9: ='Participant reporting'!C13 -> 0 | D9: ='Participant reporting'!D13 -> 0 | E9: ='Participant reporting'!E13 -> 0 | F9: ='Participant reporting'!F13 -> 0 | G9: ='Participant reporting'!G13 -> 0 | H9: ='Participant reporting'!H13 -> 0 | ... O9: ='Participant reporting'!O13 -> 0
A10: ='Participant reporting'!A14 -> 0 | B10: ='Participant reporting'!B14 -> 0 | C10: ='Participant reporting'!C14 -> 0 | D10: ='Participant reporting'!D14 -> 0 | E10: ='Participant reporting'!E14 -> 0 | F10: ='Participant reporting'!F14 -> 0 | G10: ='Participant reporting'!G14 -> 0 | H10: ='Participant reporting'!H14 -> 0 | ... O10: ='Participant reporting'!O14 -> 0
A11: ='Participant reporting'!A15 -> 0 | B11: ='Participant reporting'!B15 -> 0 | C11: ='Participant reporting'!C15 -> 0 | D11: ='Participant reporting'!D15 -> 0 | E11: ='Participant reporting'!E15 -> 0 | F11: ='Participant reporting'!F15 -> 0 | G11: ='Participant reporting'!G15 -> 0 | H11: ='Participant reporting'!H15 -> 0 | ... O11: ='Participant reporting'!O15 -> 0
A12: ='Participant reporting'!A16 -> 0 | B12: ='Participant reporting'!B16 -> 0 | C12: ='Participant reporting'!C16 -> 0 | D12: ='Participant reporting'!D16 -> 0 | E12: ='Participant reporting'!E16 -> 0 | F12: ='Participant reporting'!F16 -> 0 | G12: ='Participant reporting'!G16 -> 0 | H12: ='Participant reporting'!H16 -> 0 | ... O12: ='Participant reporting'!O16 -> 0
A13: ='Participant reporting'!A17 -> 0 | B13: ='Participant reporting'!B17 -> 0 | C13: ='Participant reporting'!C17 -> 0 | D13: ='Participant reporting'!D17 -> 0 | E13: ='Participant reporting'!E17 -> 0 | F13: ='Participant reporting'!F17 -> 0 | G13: ='Participant reporting'!G17 -> 0 | H13: ='Participant reporting'!H17 -> 0 | ... O13: ='Participant reporting'!O17 -> 0
... A29: ='Participant reporting'!A33 -> 0 | B29: ='Participant reporting'!B33 -> 0 | C29: ='Participant reporting'!C33 -> 0 | D29: ='Participant reporting'!D33 -> 0 | E29: ='Participant reporting'!E33 -> 0 | F29: ='Participant reporting'!F33 -> 0 | G29: ='Participant reporting'!G33 -> 0 | H29: ='Participant reporting'!H33 -> 0 | ... O29: ='Participant reporting'!O33 -> 0
A30: ='Participant reporting'!A257 -> 0 | B30: ='Participant reporting'!B257 -> 0 | C30: ='Participant reporting'!C257 -> 0 | D30: ='Participant reporting'!D257 -> 0 | E30: ='Participant reporting'!E257 -> 0 | F30: ='Participant reporting'!F257 -> 0 | G30: ='Participant reporting'!G257 -> 0 | H30: ='Participant reporting'!H257 -> 0 | ... O30: ='Participant reporting'!O257 -> 0
A31: ='Participant reporting'!A258 -> 0 | B31: ='Participant reporting'!B258 -> 0 | C31: ='Participant reporting'!C258 -> 0 | D31: ='Participant reporting'!D258 -> 0 | E31: ='Participant reporting'!E258 -> 0 | F31: ='Participant reporting'!F258 -> 0 | G31: ='Participant reporting'!G258 -> 0 | H31: ='Participant reporting'!H258 -> 0 | ... O31: ='Participant reporting'!O258 -> 0
A32: ='Participant reporting'!A259 -> 0 | B32: ='Participant reporting'!B259 -> 0 | C32: ='Participant reporting'!C259 -> 0 | D32: ='Participant reporting'!D259 -> 0 | E32: ='Participant reporting'!E259 -> 0 | F32: ='Participant reporting'!F259 -> 0 | G32: ='Participant reporting'!G259 -> 0 | H32: ='Participant reporting'!H259 -> 0 | ... O32: ='Participant reporting'!O259 -> 0
A33: ='Participant reporting'!A260 -> 0 | B33: ='Participant reporting'!B260 -> 0 | C33: ='Participant reporting'!C260 -> 0 | D33: ='Participant reporting'!D260 -> 0 | E33: ='Participant reporting'!E260 -> 0 | F33: ='Participant reporting'!F260 -> 0 | G33: ='Participant reporting'!G260 -> 0 | H33: ='Participant reporting'!H260 -> 0 | ... O33: ='Participant reporting'!O260 -> 0
A34: ='Participant reporting'!A261 -> 0 | B34: ='Participant reporting'!B261 -> 0 | C34: ='Participant reporting'!C261 -> 0 | D34: ='Participant reporting'!D261 -> 0 | E34: ='Participant reporting'!E261 -> 0 | F34: ='Participant reporting'!F261 -> 0 | G34: ='Participant reporting'!G261 -> 0 | H34: ='Participant reporting'!H261 -> 0 | ... O34: ='Participant reporting'!O261 -> 0
A35: ='Participant reporting'!A262 -> 0 | B35: ='Participant reporting'!B262 -> 0 | C35: ='Participant reporting'!C262 -> 0 | D35: ='Participant reporting'!D262 -> 0 | E35: ='Participant reporting'!E262 -> 0 | F35: ='Participant reporting'!F262 -> 0 | G35: ='Participant reporting'!G262 -> 0 | H35: ='Participant reporting'!H262 -> 0 | ... O35: ='Participant reporting'!O262 -> 0
A36: ='Participant reporting'!A263 -> 0 | B36: ='Participant reporting'!B263 -> 0 | C36: ='Participant reporting'!C263 -> 0 | D36: ='Participant reporting'!D263 -> 0 | E36: ='Participant reporting'!E263 -> 0 | F36: ='Participant reporting'!F263 -> 0 | G36: ='Participant reporting'!G263 -> 0 | H36: ='Participant reporting'!H263 -> 0 | ... O36: ='Participant reporting'!O263 -> 0
A37: ='Participant reporting'!A264 -> 0 | B37: ='Participant reporting'!B264 -> 0 | C37: ='Participant reporting'!C264 -> 0 | D37: ='Participant reporting'!D264 -> 0 | E37: ='Participant reporting'!E264 -> 0 | F37: ='Participant reporting'!F264 -> 0 | G37: ='Participant reporting'!G264 -> 0 | H37: ='Participant reporting'!H264 -> 0 | ... O37: ='Participant reporting'!O264 -> 0
A38: ='Participant reporting'!A265 -> 0 | B38: ='Participant reporting'!B265 -> 0 | C38: ='Participant reporting'!C265 -> 0 | D38: ='Participant reporting'!D265 -> 0 | E38: ='Participant reporting'!E265 -> 0 | F38: ='Participant reporting'!F265 -> 0 | G38: ='Participant reporting'!G265 -> 0 | H38: ='Participant reporting'!H265 -> 0 | ... O38: ='Participant reporting'!O265 -> 0
A39: ='Participant reporting'!A266 -> 0 | B39: ='Participant reporting'!B266 -> 0 | C39: ='Participant reporting'!C266 -> 0 | D39: ='Participant reporting'!D266 -> 0 | E39: ='Participant reporting'!E266 -> 0 | F39: ='Participant reporting'!F266 -> 0 | G39: ='Participant reporting'!G266 -> 0 | H39: ='Participant reporting'!H266 -> 0 | ... O39: ='Participant reporting'!O266 -> 0
A40: ='Participant reporting'!A267 -> 0 | B40: ='Participant reporting'!B267 -> 0 | C40: ='Participant reporting'!C267 -> 0 | D40: ='Participant reporting'!D267 -> 0 | E40: ='Participant reporting'!E267 -> 0 | F40: ='Participant reporting'!F267 -> 0 | G40: ='Participant reporting'!G267 -> 0 | H40: ='Participant reporting'!H267 -> 0 | ... O40: ='Participant reporting'!O267 -> 0
A41: ='Participant reporting'!A268 -> 0 | B41: ='Participant reporting'!B268 -> 0 | C41: ='Participant reporting'!C268 -> 0 | D41: ='Participant reporting'!D268 -> 0 | E41: ='Participant reporting'!E268 -> 0 | F41: ='Participant reporting'!F268 -> 0 | G41: ='Participant reporting'!G268 -> 0 | H41: ='Participant reporting'!H268 -> 0 | ... O41: ='Participant reporting'!O268 -> 0
... A1001: ='Participant reporting'!A1228 -> 0 | B1001: ='Participant reporting'!B1228 -> 0 | C1001: ='Participant reporting'!C1228 -> 0 | D1001: ='Participant reporting'!D1228 -> 0 | E1001: ='Participant reporting'!E1228 -> 0 | F1001: ='Participant reporting'!F1228 -> 0 | G1001: ='Participant reporting'!G1228 -> 0 | H1001: ='Participant reporting'!H1228 -> 0 | ... O1001: ='Participant reporting'!O1228 -> 0

Sheet Quarter 1 report
B2: Australian Skills Guarantee
B3: Quarterly Summary Report
B4: Use this sheet to report the quarterly summary information of your project.
B5: Please complete the Participant reporting for the relevant quarter first.
B7: Project Name | C7: ='Project details'!C7 -> 0
B8: Eligible project type | C8: ='Project details'!C8 -> 0
B9: Reporting year | C9: 2025
B10: Quarter | C10: 1
B12: Quarterly performance
C13: Reported hours | D13: Total reference hours | F13: Actual proportion | G13: Annual target
B14: Overall Apprentices/Cadets | C14: =SUMIFS('Participant reporting'!K:K,'Participant reporting'!A:A,'Quarter 1 report'!$C$9,'Participant reporting'!B:B,'Quarter 1 report'!$C$10)+SUMIFS('Participant reporting'!L:L,'Participant reporting'!A:A,'Quarter 1 report'!$C$9,'Participant reporting'!B:B,'Quarter 1 report'!$C$10) -> 0 | D14: =IFERROR(VLOOKUP(_xlfn.CONCAT(C9," ",B10," ",C10),Estimates!$D$9:$H$48,5,FALSE),) -> 0 | F14: =IFERROR(C14/D14,"Input data") -> Input data | G14: =IFERROR(VLOOKUP($C$9,'Project details'!$E$16:$J$25,4,FALSE),"Select Year") -> 0.1
B15: Women Apprentices | C15: =SUMIFS('Participant reporting'!K:K,'Participant reporting'!A:A,'Quarter 1 report'!$C$9,'Participant reporting'!B:B,'Quarter 1 report'!$C$10,'Participant reporting'!I:I,"Female")+SUMIFS('Participant reporting'!L:L,'Participant reporting'!A:A,'Quarter 1 report'!$C$9,'Participant reporting'!B:B,'Quarter 1 report'!$C$10,'Participant reporting'!I:I,"Female") -> 0 | D15: =C14 -> 0 | F15: =IFERROR(C15/D15,"Input data") -> Input data | G15: =IFERROR(VLOOKUP($C$9,'Project details'!$E$16:$J$25,5,FALSE),"Select Year") -> 0.06
B16: Women in Trades | C16: =IF(C8='List values'!B3,"-",SUMIFS('Participant reporting'!K:K,'Participant reporting'!A:A,'Quarter 1 report'!$C$9,'Participant reporting'!B:B,'Quarter 1 report'!$C$10,'Participant reporting'!I:I,"Female",'Participant reporting'!J:J,"Yes")+SUMIFS('Participant reporting'!L:L,'Participant reporting'!A:A,'Quarter 1 report'!$C$9,'Participant reporting'!B:B,'Quarter 1 report'!$C$10,'Participant reporting'!I:I,"Female",'Participant reporting'!J:J,"Yes")) -> 0 | D16: =IF(C8='List values'!B3,"-",SUMIFS('Participant reporting'!K:K,'Participant reporting'!A:A,$C$9,'Participant reporting'!B:B,$C$10,'Participant reporting'!J:J,"Yes")+SUMIFS('Participant reporting'!L:L,'Participant reporting'!A:A,$C$9,'Participant reporting'!B:B,$C$10,'Participant reporting'!J:J,"Yes")) -> 0 | F16: =IF(C8='List values'!B3,"-",IFERROR(C16/D16,"Input data")) -> Input data | G16: =IFERROR(IF(C8='List values'!B3,"-",VLOOKUP($C$9,'Project details'!$E$16:$J$25,6,FALSE)),"Select Year") -> 0.04
B18: Project performance to date
C19: Reported hours | D19: Total reference hours | F19: Actual proportion
B20: Overall Apprentices | C20: =SUMIFS('Participant reporting'!K:K,'Participant reporting'!A:A,"<="&'Quarter 1 report'!$C$9,'Participant reporting'!B:B,"<="&'Quarter 1 report'!$C$10)+SUMIFS('Participant reporting'!L:L,'Participant reporting'!A:A,"<="&'Quarter 1 report'!$C$9,'Participant reporting'!B:B,"<="&'Quarter 1 report'!$C$10) -> 0 | D20: =SUMIFS(Estimates!$H$9:$H$49,Estimates!$B$9:$B$49,"<="&$C$9,Estimates!$C$9:$C$49,"<="&$C$10) -> 0 | F20: =IFERROR(C20/D20,"Input data") -> Input data
B21: Women Apprentices | C21: =SUMIFS('Participant reporting'!K:K,'Participant reporting'!A:A,"<="&'Quarter 1 report'!$C$9,'Participant reporting'!B:B,"<="&'Quarter 1 report'!$C$10,'Participant reporting'!I:I,"Female")+SUMIFS('Participant reporting'!L:L,'Participant reporting'!A:A,"<="&'Quarter 1 report'!$C$9,'Participant reporting'!B:B,"<="&'Quarter 1 report'!$C$10,'Participant reporting'!I:I,"Female") -> 0 | D21: =C20 -> 0 | F21: =IFERROR(C21/D21,"Input data") -> Input data
B22: Women in Trades | C22: =IF(C8='List values'!B3,"-",SUMIFS('Participant reporting'!K:K,'Participant reporting'!A:A,"<="&'Quarter 1 report'!$C$9,'Participant reporting'!B:B,"<="&'Quarter 1 report'!$C$10,'Participant reporting'!I:I,"Female",'Participant reporting'!J:J,"Yes")+SUMIFS('Participant reporting'!L:L,'Participant reporting'!A:A,"<="&'Quarter 1 report'!$C$9,'Participant reporting'!B:B,"<="&'Quarter 1 report'!$C$10,'Participant reporting'!I:I,"Female",'Participant reporting'!J:J,"Yes")) -> 0 | D22: =IF(C8='List values'!B3,"-",SUMIFS('Participant reporting'!K:K,'Participant reporting'!A:A,"<="&'Quarter 1 report'!$C$9,'Participant reporting'!B:B,"<="&'Quarter 1 report'!$C$10,'Participant reporting'!J:J,"Yes")+SUMIFS('Participant reporting'!L:L,'Participant reporting'!A:A,"<="&'Quarter 1 report'!$C$9,'Participant reporting'!B:B,"<="&'Quarter 1 report'!$C$10,'Participant reporting'!J:J,"Yes")) -> 0 | F22: =IF(C8='List values'!B3,"-",IFERROR(C22/D22,"Input data")) -> Input data
B24: Supplier declaration
B25: In submitting this report, the Supplier declares to the best of their knowledge the information reported is true and correct at the time of submission, and understand that giving false or misleading information is a serious offence.
B28: Supplier Report details
B29: Supplier to complete this section and submit to relevant agency.
B31: Quarterly targets met: | C31: =IF(AND(ISNUMBER(F14),ISNUMBER(F15),ISNUMBER(F16)),IF(AND(F14>=G14,F15>=G15,F16>=G16),"Yes","No"),"Input data") -> Input data
B32: Reason targets were not met | F32: Other
B33: Will this limit you meeting targets in future quarters?
B34: How will you address these reasons to meet future targets?
B36: Additional report comments
B38: Gender equality action plan assessment
B39: Supplier to complete this section and submit to relevant agency.
B41: Recruitment assessment
B42: Recruitment comments
B44: Retention assessment
B45: Retention comments
B47: Other goal assessment
B48: Other goal comments
B50: Contracting Agency Assessment
B51: Agency to complete this section and submit to DEWR
B53: Assessment outcome | F53: Other
B54: Assessment notes
B56: Is the supplier well-positioned to meet the targets for future quarters?
...

Sheet Quarter 2 report
B2: Australian Skills Guarantee
B3: Quarterly Summary Report
B4: Use this sheet to report the quarterly summary information of your project.
B5: Please complete the Participant reporting for the relevant quarter first.
B7: Project Name | C7: ='Project details'!C7 -> 0
B8: Eligible project type | C8: ='Project details'!C8 -> 0
B9: Reporting year | C9: 2025
B10: Quarter | C10: 2
B12: Quarterly performance
C13: Reported hours | D13: Total reference hours | F13: Actual proportion | G13: Annual target
B14: Overall Apprentices/Cadets | C14: =SUMIFS('Participant reporting'!K:K,'Participant reporting'!A:A,'Quarter 2 report'!$C$9,'Participant reporting'!B:B,'Quarter 2 report'!$C$10)+SUMIFS('Participant reporting'!L:L,'Participant reporting'!A:A,'Quarter 2 report'!$C$9,'Participant reporting'!B:B,'Quarter 2 report'!$C$10) -> 0 | D14: =IFERROR(VLOOKUP(_xlfn.CONCAT(C9," ",B10," ",C10),Estimates!$D$9:$H$48,5,FALSE),) -> 0 | F14: =IFERROR(C14/D14,"Input data") -> Input data | G14: =IFERROR(VLOOKUP($C$9,'Project details'!$E$16:$J$25,4,FALSE),"Select Year") -> 0.1
B15: Women Apprentices | C15: =SUMIFS('Participant reporting'!K:K,'Participant reporting'!A:A,'Quarter 2 report'!$C$9,'Participant reporting'!B:B,'Quarter 2 report'!$C$10,'Participant reporting'!I:I,"Female")+SUMIFS('Participant reporting'!L:L,'Participant reporting'!A:A,'Quarter 2 report'!$C$9,'Participant reporting'!B:B,'Quarter 2 report'!$C$10,'Participant reporting'!I:I,"Female") -> 0 | D15: =C14 -> 0 | F15: =IFERROR(C15/D15,"Input data") -> Input data | G15: =IFERROR(VLOOKUP($C$9,'Project details'!$E$16:$J$25,5,FALSE),"Select Year") -> 0.06
B16: Women in Trades | C16: =IF(C8='List values'!B3,"-",SUMIFS('Participant reporting'!K:K,'Participant reporting'!A:A,'Quarter 2 report'!$C$9,'Participant reporting'!B:B,'Quarter 2 report'!$C$10,'Participant reporting'!I:I,"Female",'Participant reporting'!J:J,"Yes")+SUMIFS('Participant reporting'!L:L,'Participant reporting'!A:A,'Quarter 2 report'!$C$9,'Participant reporting'!B:B,'Quarter 2 report'!$C$10,'Participant reporting'!I:I,"Female",'Participant reporting'!J:J,"Yes")) -> 0 | D16: =IF(C8='List values'!B3,"-",SUMIFS('Participant reporting'!K:K,'Participant reporting'!A:A,$C$9,'Participant reporting'!B:B,$C$10,'Participant reporting'!J:J,"Yes")+SUMIFS('Participant reporting'!L:L,'Participant reporting'!A:A,$C$9,'Participant reporting'!B:B,$C$10,'Participant reporting'!J:J,"Yes")) -> 0 | F16: =IF(C8='List values'!B3,"-",IFERROR(C16/D16,"Input data")) -> Input data | G16: =IFERROR(IF(C8='List values'!B3,"-",VLOOKUP($C$9,'Project details'!$E$16:$J$25,6,FALSE)),"Select Year") -> 0.04
B18: Project performance to date
C19: Reported hours | D19: Total reference hours | F19: Actual proportion
B20: Overall Apprentices | C20: =SUMIFS('Participant reporting'!K:K,'Participant reporting'!A:A,"<="&'Quarter 2 report'!$C$9,'Participant reporting'!B:B,"<="&'Quarter 2 report'!$C$10)+SUMIFS('Participant reporting'!L:L,'Participant reporting'!A:A,"<="&'Quarter 2 report'!$C$9,'Participant reporting'!B:B,"<="&'Quarter 2 report'!$C$10) -> 0 | D20: =SUMIFS(Estimates!$H$9:$H$49,Estimates!$B$9:$B$49,"<="&$C$9,Estimates!$C$9:$C$49,"<="&$C$10) -> 0 | F20: =IFERROR(C20/D20,"Input data") -> Input data
B21: Women Apprentices | C21: =SUMIFS('Participant reporting'!K:K,'Participant reporting'!A:A,"<="&'Quarter 2 report'!$C$9,'Participant reporting'!B:B,"<="&'Quarter 2 report'!$C$10,'Participant reporting'!I:I,"Female")+SUMIFS('Participant reporting'!L:L,'Participant reporting'!A:A,"<="&'Quarter 2 report'!$C$9,'Participant reporting'!B:B,"<="&'Quarter 2 report'!$C$10,'Participant reporting'!I:I,"Female") -> 0 | D21: =C20 -> 0 | F21: =IFERROR(C21/D21,"Input data") -> Input data
B22: Women in Trades | C22: =IF(C8='List values'!B3,"-",SUMIFS('Participant reporting'!K:K,'Participant reporting'!A:A,"<="&'Quarter 2 report'!$C$9,'Participant reporting'!B:B,"<="&'Quarter 2 report'!$C$10,'Participant reporting'!I:I,"Female",'Participant reporting'!J:J,"Yes")+SUMIFS('Participant reporting'!L:L,'Participant reporting'!A:A,"<="&'Quarter 2 report'!$C$9,'Participant reporting'!B:B,"<="&'Quarter 2 report'!$C$10,'Participant reporting'!I:I,"Female",'Participant reporting'!J:J,"Yes")) -> 0 | D22: =IF(C8='List values'!B3,"-",SUMIFS('Participant reporting'!K:K,'Participant reporting'!A:A,"<="&'Quarter 2 report'!$C$9,'Participant reporting'!B:B,"<="&'Quarter 2 report'!$C$10,'Participant reporting'!J:J,"Yes")+SUMIFS('Participant reporting'!L:L,'Participant reporting'!A:A,"<="&'Quarter 2 report'!$C$9,'Participant reporting'!B:B,"<="&'Quarter 2 report'!$C$10,'Participant reporting'!J:J,"Yes")) -> 0 | F22: =IF(C8='List values'!B3,"-",IFERROR(C22/D22,"Input data")) -> Input data
B24: Supplier declaration
B25: In submitting this report, the Supplier declares to the best of their knowledge the information reported is true and correct at the time of submission, and understand that giving false or misleading information is a serious offence.
B28: Supplier Report details
B29: Supplier to complete this section and submit to relevant agency.
B31: Quarterly targets met: | C31: =IF(AND(ISNUMBER(F14),ISNUMBER(F15),ISNUMBER(F16)),IF(AND(F14>=G14,F15>=G15,F16>=G16),"Yes","No"),"Input data") -> Input data
B32: Reason targets were not met | F32: Other
B33: Will this limit you meeting targets in future quarters?
B34: How will you address these reasons to meet future targets?
B36: Additional report comments
B38: Gender equality action plan assessment
B39: Supplier to complete this section and submit to relevant agency.
B41: Recruitment assessment
B42: Recruitment comments
B44: Retention assessment
B45: Retention comments
B47: Other goal assessment
B48: Other goal comments
B50: Contracting Agency Assessment
B51: Agency to complete this section and submit to DEWR
B53: Assessment outcome | F53: Other
B54: Assessment notes
B56: Is the supplier well-positioned to meet the targets for future quarters?
...

Sheet Quarter 3 report
B2: Australian Skills Guarantee
B3: Quarterly Summary Report
B4: Use this sheet to report the quarterly summary information of your project.
B5: Please complete the Participant reporting for the relevant quarter first.
B7: Project Name | C7: ='Project details'!C7 -> 0
B8: Eligible project type | C8: ='Project details'!C8 -> 0
B9: Reporting year | C9: 2025
B10: Quarter | C10: 3
B12: Quarterly performance
C13: Reported hours | D13: Total reference hours | F13: Actual proportion | G13: Annual target
B14: Overall Apprentices/Cadets | C14: =SUMIFS('Participant reporting'!K:K,'Participant reporting'!A:A,'Quarter 3 report'!$C$9,'Participant reporting'!B:B,'Quarter 3 report'!$C$10)+SUMIFS('Participant reporting'!L:L,'Participant reporting'!A:A,'Quarter 3 report'!$C$9,'Participant reporting'!B:B,'Quarter 3 report'!$C$10) -> 0 | D14: =IFERROR(VLOOKUP(_xlfn.CONCAT(C9," ",B10," ",C10),Estimates!$D$9:$H$48,5,FALSE),) -> 0 | F14: =IFERROR(C14/D14,"Input data") -> Input data | G14: =IFERROR(VLOOKUP($C$9,'Project details'!$E$16:$J$25,4,FALSE),"Select Year") -> 0.1
B15: Women Apprentices | C15: =SUMIFS('Participant reporting'!K:K,'Participant reporting'!A:A,'Quarter 3 report'!$C$9,'Participant reporting'!B:B,'Quarter 3 report'!$C$10,'Participant reporting'!I:I,"Female")+SUMIFS('Participant reporting'!L:L,'Participant reporting'!A:A,'Quarter 3 report'!$C$9,'Participant reporting'!B:B,'Quarter 3 report'!$C$10,'Participant reporting'!I:I,"Female") -> 0 | D15: =C14 -> 0 | F15: =IFERROR(C15/D15,"Input data") -> Input data | G15: =IFERROR(VLOOKUP($C$9,'Project details'!$E$16:$J$25,5,FALSE),"Select Year") -> 0.06
B16: Women in Trades | C16: =IF(C8='List values'!B3,"-",SUMIFS('Participant reporting'!K:K,'Participant reporting'!A:A,'Quarter 3 report'!$C$9,'Participant reporting'!B:B,'Quarter 3 report'!$C$10,'Participant reporting'!I:I,"Female",'Participant reporting'!J:J,"Yes")+SUMIFS('Participant reporting'!L:L,'Participant reporting'!A:A,'Quarter 3 report'!$C$9,'Participant reporting'!B:B,'Quarter 3 report'!$C$10,'Participant reporting'!I:I,"Female",'Participant reporting'!J:J,"Yes")) -> 0 | D16: =IF(C8='List values'!B3,"-",SUMIFS('Participant reporting'!K:K,'Participant reporting'!A:A,$C$9,'Participant reporting'!B:B,$C$10,'Participant reporting'!J:J,"Yes")+SUMIFS('Participant reporting'!L:L,'Participant reporting'!A:A,$C$9,'Participant reporting'!B:B,$C$10,'Participant reporting'!J:J,"Yes")) -> 0 | F16: =IF(C8='List values'!B3,"-",IFERROR(C16/D16,"Input data")) -> Input data | G16: =IFERROR(IF(C8='List values'!B3,"-",VLOOKUP($C$9,'Project details'!$E$16:$J$25,6,FALSE)),"Select Year") -> 0.04
B18: Project performance to date
C19: Reported hours | D19: Total reference hours | F19: Actual proportion
B20: Overall Apprentices | C20: =SUMIFS('Participant reporting'!K:K,'Participant reporting'!A:A,"<="&'Quarter 3 report'!$C$9,'Participant reporting'!B:B,"<="&'Quarter 3 report'!$C$10)+SUMIFS('Participant reporting'!L:L,'Participant reporting'!A:A,"<="&'Quarter 3 report'!$C$9,'Participant reporting'!B:B,"<="&'Quarter 3 report'!$C$10) -> 0 | D20: =SUMIFS(Estimates!$H$9:$H$49,Estimates!$B$9:$B$49,"<="&$C$9,Estimates!$C$9:$C$49,"<="&$C$10) -> 0 | F20: =IFERROR(C20/D20,"Input data") -> Input data
B21: Women Apprentices | C21: =SUMIFS('Participant reporting'!K:K,'Participant reporting'!A:A,"<="&'Quarter 3 report'!$C$9,'Participant reporting'!B:B,"<="&'Quarter 3 report'!$C$10,'Participant reporting'!I:I,"Female")+SUMIFS('Participant reporting'!L:L,'Participant reporting'!A:A,"<="&'Quarter 3 report'!$C$9,'Participant reporting'!B:B,"<="&'Quarter 3 report'!$C$10,'Participant reporting'!I:I,"Female") -> 0 | D21: =C20 -> 0 | F21: =IFERROR(C21/D21,"Input data") -> Input data
B22: Women in Trades | C22: =IF(C8='List values'!B3,"-",SUMIFS('Participant reporting'!K:K,'Participant reporting'!A:A,"<="&'Quarter 3 report'!$C$9,'Participant reporting'!B:B,"<="&'Quarter 3 report'!$C$10,'Participant reporting'!I:I,"Female",'Participant reporting'!J:J,"Yes")+SUMIFS('Participant reporting'!L:L,'Participant reporting'!A:A,"<="&'Quarter 3 report'!$C$9,'Participant reporting'!B:B,"<="&'Quarter 3 report'!$C$10,'Participant reporting'!I:I,"Female",'Participant reporting'!J:J,"Yes")) -> 0 | D22: =IF(C8='List values'!B3,"-",SUMIFS('Participant reporting'!K:K,'Participant reporting'!A:A,"<="&'Quarter 3 report'!$C$9,'Participant reporting'!B:B,"<="&'Quarter 3 report'!$C$10,'Participant reporting'!J:J,"Yes")+SUMIFS('Participant reporting'!L:L,'Participant reporting'!A:A,"<="&'Quarter 3 report'!$C$9,'Participant reporting'!B:B,"<="&'Quarter 3 report'!$C$10,'Participant reporting'!J:J,"Yes")) -> 0 | F22: =IF(C8='List values'!B3,"-",IFERROR(C22/D22,"Input data")) -> Input data
B24: Supplier declaration
B25: In submitting this report, the Supplier declares to the best of their knowledge the information reported is true and correct at the time of submission, and understand that giving false or misleading information is a serious offence.
B28: Supplier Report details
B29: Supplier to complete this section and submit to relevant agency.
B31: Quarterly targets met: | C31: =IF(AND(ISNUMBER(F14),ISNUMBER(F15),ISNUMBER(F16)),IF(AND(F14>=G14,F15>=G15,F16>=G16),"Yes","No"),"Input data") -> Input data
B32: Reason targets were not met | F32: Other
B33: Will this limit you meeting targets in future quarters?
B34: How will you address these reasons to meet future targets?
B36: Additional report comments
B38: Gender equality action plan assessment
B39: Supplier to complete this section and submit to relevant agency.
B41: Recruitment assessment
B42: Recruitment comments
B44: Retention assessment
B45: Retention comments
B47: Other goal assessment
B48: Other goal comments
B50: Contracting Agency Assessment
B51: Agency to complete this section and submit to DEWR
B53: Assessment outcome | F53: Other
B54: Assessment notes
B56: Is the supplier well-positioned to meet the targets for future quarters?
...

Sheet Quarter 4 report
B2: Australian Skills Guarantee
B3: Quarterly Summary Report
B4: Use this sheet to report the quarterly summary information of your project.
B5: Please complete the Participant reporting for the relevant quarter first.
B7: Project Name | C7: ='Project details'!C7 -> 0
B8: Eligible project type | C8: ='Project details'!C8 -> 0
B9: Reporting year | C9: 2025
B10: Quarter | C10: 4
B12: Quarterly performance
C13: Reported hours | D13: Total reference hours | F13: Actual proportion | G13: Annual target
B14: Overall Apprentices/Cadets | C14: =SUMIFS('Participant reporting'!K:K,'Participant reporting'!A:A,'Quarter 4 report'!$C$9,'Participant reporting'!B:B,'Quarter 4 report'!$C$10)+SUMIFS('Participant reporting'!L:L,'Participant reporting'!A:A,'Quarter 4 report'!$C$9,'Participant reporting'!B:B,'Quarter 4 report'!$C$10) -> 0 | D14: =IFERROR(VLOOKUP(_xlfn.CONCAT(C9," ",B10," ",C10),Estimates!$D$9:$H$48,5,FALSE),) -> 0 | F14: =IFERROR(C14/D14,"Input data") -> Input data | G14: =IFERROR(VLOOKUP($C$9,'Project details'!$E$16:$J$25,4,FALSE),"Select Year") -> 0.1
B15: Women Apprentices | C15: =SUMIFS('Participant reporting'!K:K,'Participant reporting'!A:A,'Quarter 4 report'!$C$9,'Participant reporting'!B:B,'Quarter 4 report'!$C$10,'Participant reporting'!I:I,"Female")+SUMIFS('Participant reporting'!L:L,'Participant reporting'!A:A,'Quarter 4 report'!$C$9,'Participant reporting'!B:B,'Quarter 4 report'!$C$10,'Participant reporting'!I:I,"Female") -> 0 | D15: =C14 -> 0 | F15: =IFERROR(C15/D15,"Input data") -> Input data | G15: =IFERROR(VLOOKUP($C$9,'Project details'!$E$16:$J$25,5,FALSE),"Select Year") -> 0.06
B16: Women in Trades | C16: =IF(C8='List values'!B3,"-",SUMIFS('Participant reporting'!K:K,'Participant reporting'!A:A,'Quarter 4 report'!$C$9,'Participant reporting'!B:B,'Quarter 4 report'!$C$10,'Participant reporting'!I:I,"Female",'Participant reporting'!J:J,"Yes")+SUMIFS('Participant reporting'!L:L,'Participant reporting'!A:A,'Quarter 4 report'!$C$9,'Participant reporting'!B:B,'Quarter 4 report'!$C$10,'Participant reporting'!I:I,"Female",'Participant reporting'!J:J,"Yes")) -> 0 | D16: =IF(C8='List values'!B3,"-",SUMIFS('Participant reporting'!K:K,'Participant reporting'!A:A,$C$9,'Participant reporting'!B:B,$C$10,'Participant reporting'!J:J,"Yes")+SUMIFS('Participant reporting'!L:L,'Participant reporting'!A:A,$C$9,'Participant reporting'!B:B,$C$10,'Participant reporting'!J:J,"Yes")) -> 0 | F16: =IF(C8='List values'!B3,"-",IFERROR(C16/D16,"Input data")) -> Input data | G16: =IFERROR(IF(C8='List values'!B3,"-",VLOOKUP($C$9,'Project details'!$E$16:$J$25,6,FALSE)),"Select Year") -> 0.04
B18: Project performance to date
C19: Reported hours | D19: Total reference hours | F19: Actual proportion
B20: Overall Apprentices | C20: =SUMIFS('Participant reporting'!K:K,'Participant reporting'!A:A,"<="&'Quarter 4 report'!$C$9,'Participant reporting'!B:B,"<="&'Quarter 4 report'!$C$10)+SUMIFS('Participant reporting'!L:L,'Participant reporting'!A:A,"<="&'Quarter 4 report'!$C$9,'Participant reporting'!B:B,"<="&'Quarter 4 report'!$C$10) -> 0 | D20: =SUMIFS(Estimates!$H$9:$H$49,Estimates!$B$9:$B$49,"<="&$C$9,Estimates!$C$9:$C$49,"<="&$C$10) -> 0 | F20: =IFERROR(C20/D20,"Input data") -> Input data
B21: Women Apprentices | C21: =SUMIFS('Participant reporting'!K:K,'Participant reporting'!A:A,"<="&'Quarter 4 report'!$C$9,'Participant reporting'!B:B,"<="&'Quarter 4 report'!$C$10,'Participant reporting'!I:I,"Female")+SUMIFS('Participant reporting'!L:L,'Participant reporting'!A:A,"<="&'Quarter 4 report'!$C$9,'Participant reporting'!B:B,"<="&'Quarter 4 report'!$C$10,'Participant reporting'!I:I,"Female") -> 0 | D21: =C20 -> 0 | F21: =IFERROR(C21/D21,"Input data") -> Input data
B22: Women in Trades | C22: =IF(C8='List values'!B3,"-",SUMIFS('Participant reporting'!K:K,'Participant reporting'!A:A,"<="&'Quarter 4 report'!$C$9,'Participant reporting'!B:B,"<="&'Quarter 4 report'!$C$10,'Participant reporting'!I:I,"Female",'Participant reporting'!J:J,"Yes")+SUMIFS('Participant reporting'!L:L,'Participant reporting'!A:A,"<="&'Quarter 4 report'!$C$9,'Participant reporting'!B:B,"<="&'Quarter 4 report'!$C$10,'Participant reporting'!I:I,"Female",'Participant reporting'!J:J,"Yes")) -> 0 | D22: =IF(C8='List values'!B3,"-",SUMIFS('Participant reporting'!K:K,'Participant reporting'!A:A,"<="&'Quarter 4 report'!$C$9,'Participant reporting'!B:B,"<="&'Quarter 4 report'!$C$10,'Participant reporting'!J:J,"Yes")+SUMIFS('Participant reporting'!L:L,'Participant reporting'!A:A,"<="&'Quarter 4 report'!$C$9,'Participant reporting'!B:B,"<="&'Quarter 4 report'!$C$10,'Participant reporting'!J:J,"Yes")) -> 0 | F22: =IF(C8='List values'!B3,"-",IFERROR(C22/D22,"Input data")) -> Input data
B24: Supplier declaration
B25: In submitting this report, the Supplier declares to the best of their knowledge the information reported is true and correct at the time of submission, and understand that giving false or misleading information is a serious offence.
B28: Supplier Report details
B29: Supplier to complete this section and submit to relevant agency.
B31: Quarterly targets met: | C31: =IF(AND(ISNUMBER(F14),ISNUMBER(F15),ISNUMBER(F16)),IF(AND(F14>=G14,F15>=G15,F16>=G16),"Yes","No"),"Input data") -> Input data
B32: Reason targets were not met | F32: Other
B33: Will this limit you meeting targets in future quarters?
B34: How will you address these reasons to meet future targets?
B36: Additional report comments
B38: Gender equality action plan assessment
B39: Supplier to complete this section and submit to relevant agency.
B41: Recruitment assessment
B42: Recruitment comments
B44: Retention assessment
B45: Retention comments
B47: Other goal assessment
B48: Other goal comments
B50: Contracting Agency Assessment
B51: Agency to complete this section and submit to DEWR
B53: Assessment outcome | F53: Other
B54: Assessment notes
B56: Is the supplier well-positioned to meet the targets for future quarters?
...

Sheet Quarterly report data
A1: Reporting year | B1: Quarter | C1: Reason targets were not met | D1: Other reason | E1: Will this limit you meeting targets in future quarters | F1: How will you address these reasons to meet future targets | G1: Additional report comments | H1: Recruitment assessment | I1: Recruitment comments | J1: Retention assessment | K1: Retention comments | L1: Other goal assessment | M1: Other goal comments | N1: Assessment outcome | O1: Other outcome | P1: Assessment notes | Q1: Is the supplier well-positioned to meet the targets for future quarters | R1: What actions are required to support the supplier in meeting future targets | S1: Were any compliance activities undertaken this quarter | T1: Which stream of non-compliance applies | U1: What action was taken | V1: Other action | W1: What were the outcomes of the compliance action | X1: Are there ongoing concerns about performance supplier compliance | Y1: What action should be taken to support supplier compliance
A2: ='Quarter 1 report'!$C$9 -> 2025 | B2: ='Quarter 1 report'!$C$10 -> 1 | C2: ='Quarter 1 report'!$C$32 -> 0 | D2: ='Quarter 1 report'!$G$32 -> 0 | E2: ='Quarter 1 report'!$C$33 -> 0 | F2: ='Quarter 1 report'!$C$34 -> 0 | G2: ='Quarter 1 report'!$C$36 -> 0 | H2: ='Quarter 1 report'!$C$41 -> 0 | I2: ='Quarter 1 report'!$C$42 -> 0 | J2: ='Quarter 1 report'!$C$44 -> 0 | K2: ='Quarter 1 report'!$C$45 -> 0 | L2: ='Quarter 1 report'!$C$47 -> 0 | M2: ='Quarter 1 report'!$C$48 -> 0 | N2: ='Quarter 1 report'!$C$53 -> 0 | O2: ='Quarter 1 report'!$G$53 -> 0 | P2: ='Quarter 1 report'!$C$54 -> 0 | Q2: ='Quarter 1 report'!$C$56 -> 0 | R2: ='Quarter 1 report'!$C$57 -> 0 | S2: ='Quarter 1 report'!$C$62 -> 0 | T2: ='Quarter 1 report'!$C$63 -> 0 | U2: ='Quarter 1 report'!$C$64 -> 0 | V2: ='Quarter 1 report'!$G$64 -> 0 | W2: ='Quarter 1 report'!$C$65 -> 0 | X2: ='Quarter 1 report'!$C$66 -> 0 | Y2: ='Quarter 1 report'!$C$67 -> 0
A3: ='Quarter 2 report'!$C$9 -> 2025 | B3: ='Quarter 2 report'!$C$10 -> 2 | C3: ='Quarter 2 report'!$C$32 -> 0 | D3: ='Quarter 2 report'!$G$32 -> 0 | E3: ='Quarter 2 report'!$C$33 -> 0 | F3: ='Quarter 2 report'!$C$34 -> 0 | G3: ='Quarter 2 report'!$C$36 -> 0 | H3: ='Quarter 2 report'!$C$41 -> 0 | I3: ='Quarter 2 report'!$C$42 -> 0 | J3: ='Quarter 2 report'!$C$44 -> 0 | K3: ='Quarter 2 report'!$C$45 -> 0 | L3: ='Quarter 2 report'!$C$47 -> 0 | M3: ='Quarter 2 report'!$C$48 -> 0 | N3: ='Quarter 2 report'!$C$53 -> 0 | O3: ='Quarter 2 report'!$G$53 -> 0 | P3: ='Quarter 2 report'!$C$54 -> 0 | Q3: ='Quarter 2 report'!$C$56 -> 0 | R3: ='Quarter 2 report'!$C$57 -> 0 | S3: ='Quarter 2 report'!$C$62 -> 0 | T3: ='Quarter 2 report'!$C$63 -> 0 | U3: ='Quarter 2 report'!$C$64 -> 0 | V3: ='Quarter 2 report'!$G$64 -> 0 | W3: ='Quarter 2 report'!$C$65 -> 0 | X3: ='Quarter 2 report'!$C$66 -> 0 | Y3: ='Quarter 2 report'!$C$67 -> 0
A4: ='Quarter 3 report'!$C$9 -> 2025 | B4: ='Quarter 3 report'!$C$10 -> 3 | C4: ='Quarter 3 report'!$C$32 -> 0 | D4: ='Quarter 3 report'!$G$32 -> 0 | E4: ='Quarter 3 report'!$C$33 -> 0 | F4: ='Quarter 3 report'!$C$34 -> 0 | G4: ='Quarter 3 report'!$C$36 -> 0 | H4: ='Quarter 3 report'!$C$41 -> 0 | I4: ='Quarter 3 report'!$C$42 -> 0 | J4: ='Quarter 3 report'!$C$44 -> 0 | K4: ='Quarter 3 report'!$C$45 -> 0 | L4: ='Quarter 3 report'!$C$47 -> 0 | M4: ='Quarter 3 report'!$C$48 -> 0 | N4: ='Quarter 3 report'!$C$53 -> 0 | O4: ='Quarter 3 report'!$G$53 -> 0 | P4: ='Quarter 3 report'!$C$54 -> 0 | Q4: ='Quarter 3 report'!$C$56 -> 0 | R4: ='Quarter 3 report'!$C$57 -> 0 | S4: ='Quarter 3 report'!$C$62 -> 0 | T4: ='Quarter 3 report'!$C$63 -> 0 | U4: ='Quarter 3 report'!$C$64 -> 0 | V4: ='Quarter 3 report'!$G$64 -> 0 | W4: ='Quarter 3 report'!$C$65 -> 0 | X4: ='Quarter 3 report'!$C$66 -> 0 | Y4: ='Quarter 3 report'!$C$67 -> 0
A5: ='Quarter 4 report'!$C$9 -> 2025 | B5: ='Quarter 4 report'!$C$10 -> 4 | C5: ='Quarter 4 report'!$C$32 -> 0 | D5: ='Quarter 4 report'!$G$32 -> 0 | E5: ='Quarter 4 report'!$C$33 -> 0 | F5: ='Quarter 4 report'!$C$34 -> 0 | G5: ='Quarter 4 report'!$C$36 -> 0 | H5: ='Quarter 4 report'!$C$41 -> 0 | I5: ='Quarter 4 report'!$C$42 -> 0 | J5: ='Quarter 4 report'!$C$44 -> 0 | K5: ='Quarter 4 report'!$C$45 -> 0 | L5: ='Quarter 4 report'!$C$47 -> 0 | M5: ='Quarter 4 report'!$C$48 -> 0 | N5: ='Quarter 4 report'!$C$53 -> 0 | O5: ='Quarter 4 report'!$G$53 -> 0 | P5: ='Quarter 4 report'!$C$54 -> 0 | Q5: ='Quarter 4 report'!$C$56 -> 0 | R5: ='Quarter 4 report'!$C$57 -> 0 | S5: ='Quarter 4 report'!$C$62 -> 0 | T5: ='Quarter 4 report'!$C$63 -> 0 | U5: ='Quarter 4 report'!$C$64 -> 0 | V5: ='Quarter 4 report'!$G$64 -> 0 | W5: ='Quarter 4 report'!$C$65 -> 0 | X5: ='Quarter 4 report'!$C$66 -> 0 | Y5: ='Quarter 4 report'!$C$67 -> 0

Sheet Financial year summary
B2: Australian Skills Guarantee
B3: End of Financial Year Summary
B4: Use this sheet to review the annual performance of the supplier for your project.
B5: Please complete the Participant reporting for the full financial year first.
B7: Project Name | C7: ='Project details'!C7 -> 0
B8: Eligible project type | C8: ='Project details'!C8 -> 0
B9: Reporting year
B11: Overall Apprentices/Cadets | D11: Target | F11: =IFERROR(VLOOKUP($C$9,'Project details'!$E$16:$J$25,4,FALSE),"Select Year") -> Select Year
C13: Reported hours | D13: Estimated total hours | F13: Actual proportion
B14: Quarter 1 | C14: =SUMIFS('Participant reporting'!K:K,'Participant reporting'!A:A,$C$9,'Participant reporting'!B:B,1)+SUMIFS('Participant reporting'!L:L,'Participant reporting'!A:A,$C$9,'Participant reporting'!B:B,1) -> 0 | D14: =IFERROR(VLOOKUP(_xlfn.CONCAT($C$9," ",B14),Estimates!$D$9:$H$48,5,FALSE),) -> 0 | F14: =IFERROR(C14/D14,"Input data") -> Input data
B15: Quarter 2 | C15: =SUMIFS('Participant reporting'!K:K,'Participant reporting'!A:A,$C$9,'Participant reporting'!B:B,2)+SUMIFS('Participant reporting'!L:L,'Participant reporting'!A:A,$C$9,'Participant reporting'!B:B,2) -> 0 | D15: =IFERROR(VLOOKUP(_xlfn.CONCAT($C$9," ",B15),Estimates!$D$9:$H$48,5,FALSE),) -> 0 | F15: =IFERROR(C15/D15,"Input data") -> Input data
B16: Quarter 3 | C16: =SUMIFS('Participant reporting'!K:K,'Participant reporting'!A:A,$C$9,'Participant reporting'!B:B,3)+SUMIFS('Participant reporting'!L:L,'Participant reporting'!A:A,$C$9,'Participant reporting'!B:B,3) -> 0 | D16: =IFERROR(VLOOKUP(_xlfn.CONCAT($C$9," ",B16),Estimates!$D$9:$H$48,5,FALSE),) -> 0 | F16: =IFERROR(C16/D16,"Input data") -> Input data
B17: Quarter 4 | C17: =SUMIFS('Participant reporting'!K:K,'Participant reporting'!A:A,$C$9,'Participant reporting'!B:B,4)+SUMIFS('Participant reporting'!L:L,'Participant reporting'!A:A,$C$9,'Participant reporting'!B:B,4) -> 0 | D17: =IFERROR(VLOOKUP(_xlfn.CONCAT($C$9," ",B17),Estimates!$D$9:$H$48,5,FALSE),) -> 0 | F17: =IFERROR(C17/D17,"Input data") -> Input data
B18: Annual total | C18: =SUMIFS('Participant reporting'!K:K,'Participant reporting'!A:A,$C$9)+SUMIFS('Participant reporting'!L:L,'Participant reporting'!A:A,$C$9) -> 0 | D18: =IFERROR(VLOOKUP(C9,'Project details'!$E$16:$J$25,2,FALSE),) -> 0 | F18: =IFERROR(C18/D18,"Input data") -> Input data
B20: Women Apprentice metrics | D20: Target | F20: =IFERROR(VLOOKUP($C$9,'Project details'!$E$16:$J$25,5,FALSE),"Select Year") -> Select Year
C22: Reported hours | D22: Total reference hours | F22: Actual proportion
B23: Quarter 1 | C23: =SUMIFS('Participant reporting'!K:K,'Participant reporting'!A:A,$C$9,'Participant reporting'!B:B,1,'Participant reporting'!I:I,"Female")+SUMIFS('Participant reporting'!L:L,'Participant reporting'!A:A,$C$9,'Participant reporting'!B:B,1,'Participant reporting'!I:I,"Female") -> 0 | D23: =C14 -> 0 | F23: =IFERROR(C23/D23,"Input data") -> Input data
B24: Quarter 2 | C24: =SUMIFS('Participant reporting'!K:K,'Participant reporting'!A:A,$C$9,'Participant reporting'!B:B,2,'Participant reporting'!I:I,"Female")+SUMIFS('Participant reporting'!L:L,'Participant reporting'!A:A,$C$9,'Participant reporting'!B:B,2,'Participant reporting'!I:I,"Female") -> 0 | D24: =C15 -> 0 | F24: =IFERROR(C24/D24,"Input data") -> Input data
B25: Quarter 3 | C25: =SUMIFS('Participant reporting'!K:K,'Participant reporting'!A:A,$C$9,'Participant reporting'!B:B,3,'Participant reporting'!I:I,"Female")+SUMIFS('Participant reporting'!L:L,'Participant reporting'!A:A,$C$9,'Participant reporting'!B:B,3,'Participant reporting'!I:I,"Female") -> 0 | D25: =C16 -> 0 | F25: =IFERROR(C25/D25,"Input data") -> Input data
B26: Quarter 4 | C26: =SUMIFS('Participant reporting'!K:K,'Participant reporting'!A:A,$C$9,'Participant reporting'!B:B,4,'Participant reporting'!I:I,"Female")+SUMIFS('Participant reporting'!L:L,'Participant reporting'!A:A,$C$9,'Participant reporting'!B:B,4,'Participant reporting'!I:I,"Female") -> 0 | D26: =C17 -> 0 | F26: =IFERROR(C26/D26,"Input data") -> Input data
B27: Annual total | C27: =SUMIFS('Participant reporting'!K:K,'Participant reporting'!A:A,$C$9,'Participant reporting'!I:I,"Female")+SUMIFS('Participant reporting'!L:L,'Participant reporting'!A:A,$C$9,'Participant reporting'!I:I,"Female") -> 0 | D27: =C18 -> 0 | F27: =IFERROR(C27/D27,"Input data") -> Input data
B29: Women in Trades metrics | D29: Target | F29: =IFERROR(IF($C$8='List values'!$B$3,"-",VLOOKUP($C$9,'Project details'!$E$16:$J$25,6,FALSE)),"Select Year") -> Select Year
C31: Reported hours | D31: Total reference hours | F31: Actual proportion
B32: Quarter 1 | C32: =IF($C$8='List values'!$B$3,"-",SUMIFS('Participant reporting'!K:K,'Participant reporting'!A:A,$C$9,'Participant reporting'!B:B,1,'Participant reporting'!I:I,"Female",'Participant reporting'!J:J,"Yes")+SUMIFS('Participant reporting'!L:L,'Participant reporting'!A:A,$C$9,'Participant reporting'!B:B,1,'Participant reporting'!I:I,"Female",'Participant reporting'!J:J,"Yes")) -> 0 | D32: =IF($C$8='List values'!$B$3,"-",SUMIFS('Participant reporting'!K:K,'Participant reporting'!A:A,$C$9,'Participant reporting'!B:B,1,'Participant reporting'!J:J,"Yes")+SUMIFS('Participant reporting'!L:L,'Participant reporting'!A:A,$C$9,'Participant reporting'!B:B,1,'Participant reporting'!J:J,"Yes")) -> 0 | F32: =IF($C$8='List values'!$B$3,"-",IFERROR(C32/D32,"Input data")) -> Input data
B33: Quarter 2 | C33: =IF($C$8='List values'!$B$3,"-",SUMIFS('Participant reporting'!K:K,'Participant reporting'!A:A,$C$9,'Participant reporting'!B:B,2,'Participant reporting'!I:I,"Female",'Participant reporting'!J:J,"Yes")+SUMIFS('Participant reporting'!L:L,'Participant reporting'!A:A,$C$9,'Participant reporting'!B:B,2,'Participant reporting'!I:I,"Female",'Participant reporting'!J:J,"Yes")) -> 0 | D33: =IF($C$8='List values'!$B$3,"-",SUMIFS('Participant reporting'!K:K,'Participant reporting'!A:A,$C$9,'Participant reporting'!B:B,2,'Participant reporting'!J:J,"Yes")+SUMIFS('Participant reporting'!L:L,'Participant reporting'!A:A,$C$9,'Participant reporting'!B:B,2,'Participant reporting'!J:J,"Yes")) -> 0 | F33: =IF($C$8='List values'!$B$3,"-",IFERROR(C33/D33,"Input data")) -> Input data
B34: Quarter 3 | C34: =IF($C$8='List values'!$B$3,"-",SUMIFS('Participant reporting'!K:K,'Participant reporting'!A:A,$C$9,'Participant reporting'!B:B,3,'Participant reporting'!I:I,"Female",'Participant reporting'!J:J,"Yes")+SUMIFS('Participant reporting'!L:L,'Participant reporting'!A:A,$C$9,'Participant reporting'!B:B,3,'Participant reporting'!I:I,"Female",'Participant reporting'!J:J,"Yes")) -> 0 | D34: =IF($C$8='List values'!$B$3,"-",SUMIFS('Participant reporting'!K:K,'Participant reporting'!A:A,$C$9,'Participant reporting'!B:B,3,'Participant reporting'!J:J,"Yes")+SUMIFS('Participant reporting'!L:L,'Participant reporting'!A:A,$C$9,'Participant reporting'!B:B,3,'Participant reporting'!J:J,"Yes")) -> 0 | F34: =IF($C$8='List values'!$B$3,"-",IFERROR(C34/D34,"Input data")) -> Input data
B35: Quarter 4 | C35: =IF($C$8='List values'!$B$3,"-",SUMIFS('Participant reporting'!K:K,'Participant reporting'!A:A,$C$9,'Participant reporting'!B:B,4,'Participant reporting'!I:I,"Female",'Participant reporting'!J:J,"Yes")+SUMIFS('Participant reporting'!L:L,'Participant reporting'!A:A,$C$9,'Participant reporting'!B:B,4,'Participant reporting'!I:I,"Female",'Participant reporting'!J:J,"Yes")) -> 0 | D35: =IF($C$8='List values'!$B$3,"-",SUMIFS('Participant reporting'!K:K,'Participant reporting'!A:A,$C$9,'Participant reporting'!B:B,4,'Participant reporting'!J:J,"Yes")+SUMIFS('Participant reporting'!L:L,'Participant reporting'!A:A,$C$9,'Participant reporting'!B:B,4,'Participant reporting'!J:J,"Yes")) -> 0 | F35: =IF($C$8='List values'!$B$3,"-",IFERROR(C35/D35,"Input data")) -> Input data
B36: Annual total | C36: =IF($C$8='List values'!$B$3,"-",SUMIFS('Participant reporting'!K:K,'Participant reporting'!A:A,$C$9,'Participant reporting'!I:I,"Female",'Participant reporting'!J:J,"Yes")+SUMIFS('Participant reporting'!L:L,'Participant reporting'!A:A,$C$9,'Participant reporting'!I:I,"Female",'Participant reporting'!J:J,"Yes")) -> 0 | D36: =IF(C8='List values'!B3,"-",SUMIFS('Participant reporting'!K:K,'Participant reporting'!A:A,$C$9,'Participant reporting'!J:J,"Yes")+SUMIFS('Participant reporting'!L:L,'Participant reporting'!A:A,$C$9,'Participant reporting'!J:J,"Yes")) -> 0 | F36: =IF(C8='List values'!B3,"-",IFERROR(C36/D36,"Input data")) -> Input data

Sheet End of project report
B2: Australian Skills Guarantee
B3: End of Project Report
B4: Use this sheet to assess the overall project performance of the supplier for your project.
B5: Please complete the Participant reporting for all financial years first.
B7: Project Name | C7: ='Project details'!C7 -> 0
B8: Eligible project type | C8: ='Project details'!C8 -> 0
B10: Overall performance
C11: Reported hours | D11: Total reference hours | F11: Actual proportion | G11: Average target
